Workbook

Sheet READ ME
A1: narve.ai — Financial Model
A2: Built July 2, 2026. All prices researched against official/current sources (see Assumptions tab for URLs).
A4: TABS
A5: Assumptions — every researched price with source. Edit the yellow cells; Costs/P&L/Raise recalculate.
A6: Costs — monthly operating costs in 3 scenarios: Bootstrap (today), Funded pre-seed, Full fleet revival.
A7: Projections — 24-month subscriber & MRR model, 3 growth cases, driven by editable growth/churn/ARPU cells.
A8: P&L (Accounting) — monthly profit & loss for the Funded plan: revenue, Stripe fees, COGS, opex, EBITDA, cash.
A9: Raise & Runway — how much to raise: peak cumulative cash need + buffer, with a 12/18/24-month sensitivity table.
A11: HEADLINES (Funded pre-seed plan, Base growth case)
A12: Monthly burn before revenue: ≈ $10,100/mo. One-time setup (incorporation + legal + regulatory memo): ≈ $20,500.
A13: Recommended raise: see Raise & Runway tab — peak cash need over 24 months plus a 25% buffer.
A15: KEY CAVEATS
... A22: • Sonnet 5 API pricing is introductory ($2/$10 per MTok) until 2026-08-31, then $3/$15.

Sheet Assumptions
A1: Assumptions — researched prices (as of 2026-07-02)
A3: AWS (us-east-1)
A4: Item | B4: Tier / plan | C4: Price $ | D4: Unit | E4: Source
A5: EC2 t3.large (2 vCPU / 8 GiB) | B5: On-demand | C5: 60.74 | D5: per month (730h) | E5: aws.amazon.com/ec2/pricing/on-demand/
A6: EC2 t3.xlarge (4 vCPU / 16 GiB) | B6: On-demand | C6: 121.47 | D6: per month (730h) | E6: aws.amazon.com/ec2/pricing/on-demand/
A7: EC2 t3.xlarge (4 vCPU / 16 GiB) | B7: 1-yr no-upfront reserved | C7: 76.14 | D7: per month (730h) | E7: aws.amazon.com/ec2/pricing/reserved-instances/
A8: EC2 m7i-flex.xlarge (4 vCPU / 16 GiB) | B8: 1-yr no-upfront reserved | C8: 92.48 | D8: per month (730h) | E8: aws.amazon.com/savingsplans/compute-pricing/
A9: EBS gp3 storage | B9: standard | C9: 0.08 | D9: per GB-month (3k IOPS incl.) | E9: aws.amazon.com/ebs/pricing/
A10: EBS snapshots | B10: standard | C10: 0.05 | D10: per GB-month (incremental) | E10: aws.amazon.com/ebs/pricing/
A11: S3 Standard | B11: first 50 TB | C11: 0.023 | D11: per GB-month | E11: aws.amazon.com/s3/pricing/
A12: Data transfer out | B12: after 100 GB free | C12: 0.09 | D12: per GB (first 10 TB) | E12: aws.amazon.com/ec2/pricing/on-demand/
A13: ElastiCache cache.t4g.micro (Redis) | B13: on-demand | C13: 11.68 | D13: per month | E13: aws.amazon.com/elasticache/pricing/
A14: ALB (optional — skipped, Cloudflare Tunnel used) | B14: hourly + 1 LCU | C14: 22.27 | D14: per month | E14: aws.amazon.com/elasticloadbalancing/pricing/
A16: Data & AI APIs
A17: Item | B17: Tier / plan | C17: Price $ | D17: Unit | E17: Source
A18: The Odds API | B18: Free / 20K / 100K | C18: 30 | D18: per month (20K credits tier) | E18: the-odds-api.com
A19: Open-Meteo commercial | B19: API Standard (1M calls/mo) | C19: 33 | D19: per month (EUR 29) | E19: open-meteo.com/en/pricing
A20: Anthropic Claude — Haiku 4.5 | B20: input / output | C20: 1 | D20: $1 / $5 per MTok (batch −50%) | E20: platform.claude.com/docs/en/about-claude/pricing
A21: Anthropic Claude — Sonnet 5 (intro to 2026-08-31) | B21: input / output | C21: 2 | D21: $2 / $10 per MTok, then $3/$15 | E21: platform.claude.com/docs/en/about-claude/pricing
A22: X API v2 pay-per-use | B22: post reads | C22: 0.005 | D22: per post read (2M/mo cap) | E22: docs.x.com
A23: Alpaca market data | B23: Algo Trader Plus (full SIP) | C23: 99 | D23: per month (free IEX tier exists) | E23: alpaca.markets/data
A24: CoinGecko API | B24: Analyst | C24: 129 | D24: per month (free 10K demo tier exists) | E24: coingecko.com/en/api/pricing
A25: Polymarket / Kalshi / Binance / yfinance / NWS / USGS / FRED / Census / BEA / BLS / FEC | B25: public | C25: 0 | D25: free (fair-use limits) | E25: various — verified free/keyless
A27: SaaS & payments
A28: Item | B28: Tier / plan | C28: Price $ | D28: Unit | E28: Source
A29: Stripe card processing | B29: US standard | C29: 2.9 | D29: % + $0.30 per charge | E29: stripe.com/pricing
A30: Stripe Billing (subscriptions) | B30: unified plan | C30: 0.7 | D30: % of billing volume | E30: stripe.com/billing/pricing
A31: .ai domain (narve.ai) | B31: Porkbun renewal | C31: 82.7 | D31: per year | E31: porkbun.com
A32: Cloudflare (DNS/CDN/Tunnel) | B32: Free | C32: 0 | D32: per month | E32: cloudflare.com/plans
A33: Tailscale | B33: Personal (free, ≤6 users) | C33: 0 | D33: per month | E33: tailscale.com/pricing
A34: Google Workspace | B34: Business Starter | C34: 7 | D34: per user / month (annual) | E34: workspace.google.com/pricing
A35: GitHub | B35: Free (2,000 CI min/mo) | C35: 0 | D35: per month | E35: github.com/pricing
A36: Sentry | B36: Developer free / Team $26 | C36: 26 | D36: per month (Team, annual) | E36: sentry.io/pricing
A37: Apple Developer Program (iOS app) | B37: individual | C37: 99 | D37: per year | E37: developer.apple.com/support/enrollment/
A38: Amazon SES (transactional email) | B38: standard | C38: 0.1 | D38: per 1,000 emails | E38: aws.amazon.com/ses/pricing/
A40: Company & professional (US Delaware C-corp)
A41: Item | B41: Tier / plan | C41: Price $ | D41: Unit | E41: Source
A42: Incorporation (Stripe Atlas) | B42: one-time | C42: 500 | D42: one-time (incl. 1st-yr agent) | E42: stripe.com/atlas
A43: Registered agent | B43: annual, from yr 2 | C43: 100 | D43: per year | E43: support.stripe.com (Atlas renewal)
A44: Delaware franchise tax + report | B44: assumed-par-value minimum | C44: 450 | D44: per year | E44: corp.delaware.gov/frtaxcalc/
...

Sheet Costs
A1: Monthly operating costs — three scenarios (USD)
A2: Bootstrap = today's trimmed 3-product fleet, no salary. Funded = pre-seed plan. Full fleet = all 12+ dashboards revived.
A4: Line item | B4: Bootstrap | C4: Funded | D4: Full fleet | E4: Basis
A5: Infrastructure (AWS, us-east-1)
A6: EC2 instance | B6: 60.74 | C6: 76.14 | D6: 168.62 | E6: Boot: t3.large on-demand. Funded: t3.xlarge 1-yr reserved. Full: t3.xlarge RI + m7i-flex.xlarge RI second box
A7: EBS gp3 volumes | B7: 4 | C7: 8 | D7: 16 | E7: 50 / 100 / 200 GB @ $0.08
A8: EBS snapshots (backups) | B8: 1.25 | C8: 2.5 | D8: 5 | E8: 25 / 50 / 100 GB @ $0.05 (incremental)
A9: S3 (snapshot.sh archives) | B9: 0.58 | C9: 1.15 | D9: 2.3 | E9: 25 / 50 / 100 GB @ $0.023
A10: Data transfer out | B10: 0 | C10: 18 | D10: 36 | E10: ≤100 GB free / ~300 GB / ~500 GB @ $0.09 after free tier
A11: Redis | B11: 0 | C11: 0 | D11: 11.68 | E11: on-box (free) until Full fleet → ElastiCache t4g.micro
A12: Amazon SES email | B12: 0.5 | C12: 1 | D12: 2 | E12: password resets, alerts @ $0.10/1k
A13: Data & AI APIs
A14: Open-Meteo commercial license | B14: 33 | C14: 33 | D14: 33 | E14: required to sell the weather product (free tier is non-commercial)
A15: The Odds API | B15: 0 | C15: 30 | D15: 59 | E15: free 500 credits / 20K tier / 100K tier (sports dashboard revived)
A16: Anthropic Claude API | B16: 10 | C16: 50 | D16: 200 | E16: email relay only / + signal explanations / + Truth LLM extraction (Haiku 4.5 batch)
A17: X API v2 (pay-per-use) | B17: 0 | C17: 0 | D17: 300 | E17: only if Truth dashboard revived: ~60k post reads/mo @ $0.005
A18: Alpaca market data | B18: 0 | C18: 0 | D18: 99 | E18: free IEX tier until stock desk needs full SIP feed
A19: CoinGecko API | B19: 0 | C19: 0 | D19: 129 | E19: free demo tier until crypto-trackers revived (Analyst)
A20: SaaS & tooling
A21: .ai domain | B21: 6.89 | C21: 6.89 | D21: 6.89 | E21: $82.70/yr Porkbun renewal ÷ 12
A22: Cloudflare / Tailscale / GitHub | B22: 0 | C22: 0 | D22: 0 | E22: free tiers cover current usage (Tunnel confirmed free)
A23: Google Workspace (1 user) | B23: 7 | C23: 7 | D23: 14 | E23: Business Starter; 2 users at Full
A24: Sentry | B24: 0 | C24: 26 | D24: 26 | E24: Developer free / Team
A25: Apple Developer (iOS app) | B25: 0 | C25: 8.25 | D25: 8.25 | E25: $99/yr ÷ 12 — CryptoEdge iOS app
A26: People & professional
A27: Founder salary | B27: 0 | C27: 6250 | D27: 6250 | E27: $75k/yr — Pilot 2025 pre-seed median
A28: Payroll taxes (10%) | B28: 0 | C28: 625 | D28: 625 | E28: employer side
A29: Part-time contractor | B29: 0 | C29: 1500 | D29: 1500 | E29: planning figure
A30: Bookkeeping (Pilot Essentials) | B30: 0 | C30: 99 | D30: 99 | E30: $99/mo
A31: Business insurance (GL+E&O+cyber) | B31: 0 | C31: 281 | D31: 281 | E31: small-SaaS averages (Insureon/TechInsurance)
A32: Compliance amortized (franchise tax, agent, tax filing) | B32: 37.5 | C32: 125 | D32: 125 | E32: Boot: DE franchise tax only. Funded: +$100 agent +$950 Fondo ÷ 12
A33: Marketing | B33: 0 | C33: 1000 | D33: 1000 | E33: planning figure
A34: TOTALS
A35: Total monthly | B35: =SUM(B6:B12,B14:B19,B21:B25,B27:B33) | C35: =SUM(C6:C12,C14:C19,C21:C25,C27:C33) | D35: =SUM(D6:D12,D14:D19,D21:D25,D27:D33)
A36: Total annual | B36: =B35*12 | C36: =C35*12 | D36: =D35*12
A38: ONE-TIME COSTS (paid once, at/around the raise)
A39: Item | B39: Amount | E39: Basis
A40: Incorporation — Stripe Atlas | B40: 500 | E40: Delaware C-corp, incl. first-year registered agent + 83(b)
A41: Pre-seed SAFE legal review | B41: 5000 | E41: YC SAFE docs are free; light counsel review $2–5k, avg pre-seed <$10k
A42: IA/CTA regulatory memo | B42: 15000 | E42: written analysis: Advisers Act publisher exclusion + CTA status for signal subscriptions ($5–25k range)
...

Sheet Projections
A1: 24-month subscriber & MRR projections (3 cases)
A2: Driven by Assumptions drivers. Subs(m) = Subs(m-1) × (1 − churn) + New(m); New grows monthly up to a cap. MRR = Subs × ARPU.
B4: Conservative | F4: Base | J4: Optimistic
A5: Month | B5: New | C5: Subs | D5: MRR $ | F5: New | G5: Subs | H5: MRR $ | J5: New | K5: Subs | L5: MRR $
A6: 1 | B6: =Assumptions!$B$62 | C6: =B6 | D6: =C6*Assumptions!$B$57 | F6: =Assumptions!$B$63 | G6: =F6 | H6: =G6*Assumptions!$B$57 | J6: =Assumptions!$B$66 | K6: =J6 | L6: =K6*Assumptions!$B$57
A7: 2 | B7: =B6 | C7: =C6*(1-Assumptions!$B$60)+B7 | D7: =C7*Assumptions!$B$57 | F7: =MIN(Assumptions!$B$65,F6*(1+Assumptions!$B$64)) | G7: =G6*(1-Assumptions!$B$60)+F7 | H7: =G7*Assumptions!$B$57 | J7: =MIN(Assumptions!$B$68,J6*(1+Assumptions!$B$67)) | K7: =K6*(1-Assumptions!$B$61)+J7 | L7: =K7*Assumptions!$B$57
A8: 3 | B8: =B7 | C8: =C7*(1-Assumptions!$B$60)+B8 | D8: =C8*Assumptions!$B$57 | F8: =MIN(Assumptions!$B$65,F7*(1+Assumptions!$B$64)) | G8: =G7*(1-Assumptions!$B$60)+F8 | H8: =G8*Assumptions!$B$57 | J8: =MIN(Assumptions!$B$68,J7*(1+Assumptions!$B$67)) | K8: =K7*(1-Assumptions!$B$61)+J8 | L8: =K8*Assumptions!$B$57
A9: 4 | B9: =B8 | C9: =C8*(1-Assumptions!$B$60)+B9 | D9: =C9*Assumptions!$B$57 | F9: =MIN(Assumptions!$B$65,F8*(1+Assumptions!$B$64)) | G9: =G8*(1-Assumptions!$B$60)+F9 | H9: =G9*Assumptions!$B$57 | J9: =MIN(Assumptions!$B$68,J8*(1+Assumptions!$B$67)) | K9: =K8*(1-Assumptions!$B$61)+J9 | L9: =K9*Assumptions!$B$57
A10: 5 | B10: =B9 | C10: =C9*(1-Assumptions!$B$60)+B10 | D10: =C10*Assumptions!$B$57 | F10: =MIN(Assumptions!$B$65,F9*(1+Assumptions!$B$64)) | G10: =G9*(1-Assumptions!$B$60)+F10 | H10: =G10*Assumptions!$B$57 | J10: =MIN(Assumptions!$B$68,J9*(1+Assumptions!$B$67)) | K10: =K9*(1-Assumptions!$B$61)+J10 | L10: =K10*Assumptions!$B$57
A11: 6 | B11: =B10 | C11: =C10*(1-Assumptions!$B$60)+B11 | D11: =C11*Assumptions!$B$57 | F11: =MIN(Assumptions!$B$65,F10*(1+Assumptions!$B$64)) | G11: =G10*(1-Assumptions!$B$60)+F11 | H11: =G11*Assumptions!$B$57 | J11: =MIN(Assumptions!$B$68,J10*(1+Assumptions!$B$67)) | K11: =K10*(1-Assumptions!$B$61)+J11 | L11: =K11*Assumptions!$B$57
A12: 7 | B12: =B11 | C12: =C11*(1-Assumptions!$B$60)+B12 | D12: =C12*Assumptions!$B$57 | F12: =MIN(Assumptions!$B$65,F11*(1+Assumptions!$B$64)) | G12: =G11*(1-Assumptions!$B$60)+F12 | H12: =G12*Assumptions!$B$57 | J12: =MIN(Assumptions!$B$68,J11*(1+Assumptions!$B$67)) | K12: =K11*(1-Assumptions!$B$61)+J12 | L12: =K12*Assumptions!$B$57
A13: 8 | B13: =B12 | C13: =C12*(1-Assumptions!$B$60)+B13 | D13: =C13*Assumptions!$B$57 | F13: =MIN(Assumptions!$B$65,F12*(1+Assumptions!$B$64)) | G13: =G12*(1-Assumptions!$B$60)+F13 | H13: =G13*Assumptions!$B$57 | J13: =MIN(Assumptions!$B$68,J12*(1+Assumptions!$B$67)) | K13: =K12*(1-Assumptions!$B$61)+J13 | L13: =K13*Assumptions!$B$57
A14: 9 | B14: =B13 | C14: =C13*(1-Assumptions!$B$60)+B14 | D14: =C14*Assumptions!$B$57 | F14: =MIN(Assumptions!$B$65,F13*(1+Assumptions!$B$64)) | G14: =G13*(1-Assumptions!$B$60)+F14 | H14: =G14*Assumptions!$B$57 | J14: =MIN(Assumptions!$B$68,J13*(1+Assumptions!$B$67)) | K14: =K13*(1-Assumptions!$B$61)+J14 | L14: =K14*Assumptions!$B$57
A15: 10 | B15: =B14 | C15: =C14*(1-Assumptions!$B$60)+B15 | D15: =C15*Assumptions!$B$57 | F15: =MIN(Assumptions!$B$65,F14*(1+Assumptions!$B$64)) | G15: =G14*(1-Assumptions!$B$60)+F15 | H15: =G15*Assumptions!$B$57 | J15: =MIN(Assumptions!$B$68,J14*(1+Assumptions!$B$67)) | K15: =K14*(1-Assumptions!$B$61)+J15 | L15: =K15*Assumptions!$B$57
A16: 11 | B16: =B15 | C16: =C15*(1-Assumptions!$B$60)+B16 | D16: =C16*Assumptions!$B$57 | F16: =MIN(Assumptions!$B$65,F15*(1+Assumptions!$B$64)) | G16: =G15*(1-Assumptions!$B$60)+F16 | H16: =G16*Assumptions!$B$57 | J16: =MIN(Assumptions!$B$68,J15*(1+Assumptions!$B$67)) | K16: =K15*(1-Assumptions!$B$61)+J16 | L16: =K16*Assumptions!$B$57
A17: 12 | B17: =B16 | C17: =C16*(1-Assumptions!$B$60)+B17 | D17: =C17*Assumptions!$B$57 | F17: =MIN(Assumptions!$B$65,F16*(1+Assumptions!$B$64)) | G17: =G16*(1-Assumptions!$B$60)+F17 | H17: =G17*Assumptions!$B$57 | J17: =MIN(Assumptions!$B$68,J16*(1+Assumptions!$B$67)) | K17: =K16*(1-Assumptions!$B$61)+J17 | L17: =K17*Assumptions!$B$57
A18: 13 | B18: =B17 | C18: =C17*(1-Assumptions!$B$60)+B18 | D18: =C18*Assumptions!$B$57 | F18: =MIN(Assumptions!$B$65,F17*(1+Assumptions!$B$64)) | G18: =G17*(1-Assumptions!$B$60)+F18 | H18: =G18*Assumptions!$B$57 | J18: =MIN(Assumptions!$B$68,J17*(1+Assumptions!$B$67)) | K18: =K17*(1-Assumptions!$B$61)+J18 | L18: =K18*Assumptions!$B$57
... A29: 24 | B29: =B28 | C29: =C28*(1-Assumptions!$B$60)+B29 | D29: =C29*Assumptions!$B$57 | F29: =MIN(Assumptions!$B$65,F28*(1+Assumptions!$B$64)) | G29: =G28*(1-Assumptions!$B$60)+F29 | H29: =G29*Assumptions!$B$57 | J29: =MIN(Assumptions!$B$68,J28*(1+Assumptions!$B$67)) | K29: =K28*(1-Assumptions!$B$61)+J29 | L29: =K29*Assumptions!$B$57
A31: Month-24 MRR | D31: =D29 | H31: =H29 | L31: =L29

Sheet P&L (Accounting)
A1: Monthly P&L — Funded pre-seed plan × Base growth case (USD)
A2: Accrual-style operating P&L; one-time costs hit month 1. Cumulative cash line drives the Raise tab.
A4: Line | B4: M1 | C4: M2 | D4: M3 | E4: M4 | F4: M5 | G4: M6 | H4: M7 | I4: M8 | J4: M9 | K4: M10 | L4: M11 | M4: M12 | N4: M13 | O4: M14 | P4: M15 | Q4: M16 | R4: M17 | S4: M18 | T4: M19 | U4: M20 | V4: M21 | W4: M22 | X4: M23 | Y4: M24
A5: Subscribers (avg) | B5: =Projections!G6 | C5: =Projections!G7 | D5: =Projections!G8 | E5: =Projections!G9 | F5: =Projections!G10 | G5: =Projections!G11 | H5: =Projections!G12 | I5: =Projections!G13 | J5: =Projections!G14 | K5: =Projections!G15 | L5: =Projections!G16 | M5: =Projections!G17 | N5: =Projections!G18 | O5: =Projections!G19 | P5: =Projections!G20 | Q5: =Projections!G21 | R5: =Projections!G22 | S5: =Projections!G23 | T5: =Projections!G24 | U5: =Projections!G25 | V5: =Projections!G26 | W5: =Projections!G27 | X5: =Projections!G28 | Y5: =Projections!G29
A6: Revenue (MRR) | B6: =Projections!H6 | C6: =Projections!H7 | D6: =Projections!H8 | E6: =Projections!H9 | F6: =Projections!H10 | G6: =Projections!H11 | H6: =Projections!H12 | I6: =Projections!H13 | J6: =Projections!H14 | K6: =Projections!H15 | L6: =Projections!H16 | M6: =Projections!H17 | N6: =Projections!H18 | O6: =Projections!H19 | P6: =Projections!H20 | Q6: =Projections!H21 | R6: =Projections!H22 | S6: =Projections!H23 | T6: =Projections!H24 | U6: =Projections!H25 | V6: =Projections!H26 | W6: =Projections!H27 | X6: =Projections!H28 | Y6: =Projections!H29
A7: Stripe fees | B7: =-(B6*Assumptions!$B$58+B5*Assumptions!$B$59) | C7: =-(C6*Assumptions!$B$58+C5*Assumptions!$B$59) | D7: =-(D6*Assumptions!$B$58+D5*Assumptions!$B$59) | E7: =-(E6*Assumptions!$B$58+E5*Assumptions!$B$59) | F7: =-(F6*Assumptions!$B$58+F5*Assumptions!$B$59) | G7: =-(G6*Assumptions!$B$58+G5*Assumptions!$B$59) | H7: =-(H6*Assumptions!$B$58+H5*Assumptions!$B$59) | I7: =-(I6*Assumptions!$B$58+I5*Assumptions!$B$59) | ... Y7: =-(Y6*Assumptions!$B$58+Y5*Assumptions!$B$59)
A8: Net revenue | B8: =B6+B7 | C8: =C6+C7 | D8: =D6+D7 | E8: =E6+E7 | F8: =F6+F7 | G8: =G6+G7 | H8: =H6+H7 | I8: =I6+I7 | ... Y8: =Y6+Y7
A9: COGS — infra + APIs | B9: =-(SUM(Costs!$C$6:$C$12)+SUM(Costs!$C$14:$C$19)) | C9: =-(SUM(Costs!$C$6:$C$12)+SUM(Costs!$C$14:$C$19)) | D9: =-(SUM(Costs!$C$6:$C$12)+SUM(Costs!$C$14:$C$19)) | E9: =-(SUM(Costs!$C$6:$C$12)+SUM(Costs!$C$14:$C$19)) | F9: =-(SUM(Costs!$C$6:$C$12)+SUM(Costs!$C$14:$C$19)) | G9: =-(SUM(Costs!$C$6:$C$12)+SUM(Costs!$C$14:$C$19)) | H9: =-(SUM(Costs!$C$6:$C$12)+SUM(Costs!$C$14:$C$19)) | I9: =-(SUM(Costs!$C$6:$C$12)+SUM(Costs!$C$14:$C$19)) | ... Y9: =-(SUM(Costs!$C$6:$C$12)+SUM(Costs!$C$14:$C$19))
A10: Gross profit | B10: =B8+B9 | C10: =C8+C9 | D10: =D8+D9 | E10: =E8+E9 | F10: =F8+F9 | G10: =G8+G9 | H10: =H8+H9 | I10: =I8+I9 | ... Y10: =Y8+Y9
A11: Gross margin % | B11: =IF(B6=0,0,B10/B6) | C11: =IF(C6=0,0,C10/C6) | D11: =IF(D6=0,0,D10/D6) | E11: =IF(E6=0,0,E10/E6) | F11: =IF(F6=0,0,F10/F6) | G11: =IF(G6=0,0,G10/G6) | H11: =IF(H6=0,0,H10/H6) | I11: =IF(I6=0,0,I10/I6) | ... Y11: =IF(Y6=0,0,Y10/Y6)
A12: Opex — people & professional | B12: =-SUM(Costs!$C$27:$C$32) | C12: =-SUM(Costs!$C$27:$C$32) | D12: =-SUM(Costs!$C$27:$C$32) | E12: =-SUM(Costs!$C$27:$C$32) | F12: =-SUM(Costs!$C$27:$C$32) | G12: =-SUM(Costs!$C$27:$C$32) | H12: =-SUM(Costs!$C$27:$C$32) | I12: =-SUM(Costs!$C$27:$C$32) | ... Y12: =-SUM(Costs!$C$27:$C$32)
A13: Opex — SaaS & tooling | B13: =-SUM(Costs!$C$21:$C$25) | C13: =-SUM(Costs!$C$21:$C$25) | D13: =-SUM(Costs!$C$21:$C$25) | E13: =-SUM(Costs!$C$21:$C$25) | F13: =-SUM(Costs!$C$21:$C$25) | G13: =-SUM(Costs!$C$21:$C$25) | H13: =-SUM(Costs!$C$21:$C$25) | I13: =-SUM(Costs!$C$21:$C$25) | ... Y13: =-SUM(Costs!$C$21:$C$25)
A14: Opex — marketing | B14: =-Costs!$C$33 | C14: =-Costs!$C$33 | D14: =-Costs!$C$33 | E14: =-Costs!$C$33 | F14: =-Costs!$C$33 | G14: =-Costs!$C$33 | H14: =-Costs!$C$33 | I14: =-Costs!$C$33 | ... Y14: =-Costs!$C$33
A15: Total opex | B15: =B12+B13+B14 | C15: =C12+C13+C14 | D15: =D12+D13+D14 | E15: =E12+E13+E14 | F15: =F12+F13+F14 | G15: =G12+G13+G14 | H15: =H12+H13+H14 | I15: =I12+I13+I14 | ... Y15: =Y12+Y13+Y14
A16: EBITDA | B16: =B10+B15 | C16: =C10+C15 | D16: =D10+D15 | E16: =E10+E15 | F16: =F10+F15 | G16: =G10+G15 | H16: =H10+H15 | I16: =I10+I15 | ... Y16: =Y10+Y15
A17: One-time costs | B17: =-Costs!$B$43 | C17: =0 | D17: =0 | E17: =0 | F17: =0 | G17: =0 | H17: =0 | I17: =0 | J17: =0 | ... Y17: =0
A18: Net cash flow | B18: =B16+B17 | C18: =C16+C17 | D18: =D16+D17 | E18: =E16+E17 | F18: =F16+F17 | G18: =G16+G17 | H18: =H16+H17 | I18: =I16+I17 | ... Y18: =Y16+Y17
A19: Cumulative cash | B19: =B18 | C19: =B19+C18 | D19: =C19+D18 | E19: =D19+E18 | F19: =E19+F18 | G19: =F19+G18 | H19: =G19+H18 | I19: =H19+I18 | J19: =I19+J18 | ... Y19: =X19+Y18

Sheet Raise & Runway
A1: How much to raise
A3: Peak cumulative cash need (Funded × Base, 24 mo) | B3: =-MIN('P&L (Accounting)'!B19:Y19) | C3: most-negative cumulative cash on the P&L tab
A4: Buffer | B4: =B3*Assumptions!$B$69 | C4: 25% cushion (edit on Assumptions)
A5: RECOMMENDED RAISE (pre-seed) | B5: =B3+B4 | C5: peak need + buffer, rounded up when pitching
A7: Sensitivity — cash needed at month N (before buffer)
A8: Horizon | B8: Cash need $ | C8: Note
A9: 12 months | B9: =-MIN('P&L (Accounting)'!B19:M19) | C9: 12-month runway
A10: 18 months | B10: =-MIN('P&L (Accounting)'!B19:S19) | C10: 18-month runway (typical pre-seed ask)
A11: 24 months | B11: =-MIN('P&L (Accounting)'!B19:Y19) | C11: 24-month runway
A13: Bootstrap alternative (no raise)
A14: Bootstrap monthly cost | B14: =Costs!$B$35 | C14: today's trimmed fleet on AWS, founder unpaid
A15: Bootstrap annual cost | B15: =Costs!$B$35*12 | C15: ≈ what it costs to keep narve.ai alive for a year
A16: Subscribers to break even (Bootstrap) | B16: =ROUNDUP(Costs!$B$35/(Assumptions!$B$57*(1-Assumptions!$B$58)-Assumptions!$B$59),0) | C16: monthly cost ÷ net ARPU
A17: Subscribers to break even (Funded) | B17: =ROUNDUP(Costs!$C$35/(Assumptions!$B$57*(1-Assumptions!$B$58)-Assumptions!$B$59),0) | C17: covers salary + full opex
